Workbook
Name NativeTimeline_Order_Date: #N/A
Name Slicer_Category: #N/A
Name Slicer_Region: #N/A
Name Slicer_Ship_Mode: #N/A

Sheet range
A1: Row ID | B1: Order ID | C1: Order Date | D1: Ship Mode | E1: Customer Name | F1: City | G1: State | H1: Region | I1: Category | J1: Sub-Category | K1: Product Name | L1: Sales | M1: Quantity | N1: Discount | O1: Profit
A2: 1 | B2: CA-2018-152156 | C2: 43412 | D2: Second Class | E2: Claire Gute | F2: Henderson | G2: Kentucky | H2: South | I2: Furniture | J2: Bookcases | K2: Bush Somerset Collection Bookcase | L2: 261.96 | M2: 2 | N2: 0 | O2: 41.9136
A3: 2 | B3: CA-2018-152156 | C3: 43412 | D3: Second Class | E3: Claire Gute | F3: Henderson | G3: Kentucky | H3: South | I3: Furniture | J3: Chairs | K3: Hon Deluxe Fabric Upholstered Stacking Chairs, Rounded Back | L3: 731.94 | M3: 3 | N3: 0 | O3: 219.582
A4: 3 | B4: CA-2018-138688 | C4: 43263 | D4: Second Class | E4: Darrin Van Huff | F4: Los Angeles | G4: California | H4: West | I4: Office Supplies | J4: Labels | K4: Self-Adhesive Address Labels for Typewriters by Universal | L4: 14.62 | M4: 2 | N4: 0 | O4: 6.8714
A5: 4 | B5: US-2017-108966 | C5: 43019 | D5: Standard Class | E5: Sean O'Donnell | F5: Fort Lauderdale | G5: Florida | H5: South | I5: Furniture | J5: Tables | K5: Bretford CR4500 Series Slim Rectangular Table | L5: 957.5775 | M5: 5 | N5: 0.45 | O5: -383.031
A6: 5 | B6: US-2017-108966 | C6: 43019 | D6: Standard Class | E6: Sean O'Donnell | F6: Fort Lauderdale | G6: Florida | H6: South | I6: Office Supplies | J6: Storage | K6: Eldon Fold 'N Roll Cart System | L6: 22.368 | M6: 2 | N6: 0.2 | O6: 2.5164
A7: 6 | B7: CA-2016-115812 | C7: 42530 | D7: Standard Class | E7: Brosina Hoffman | F7: Los Angeles | G7: California | H7: West | I7: Furniture | J7: Furnishings | K7: Eldon Expressions Wood and Plastic Desk Accessories, Cherry Wood | L7: 48.86 | M7: 7 | N7: 0 | O7: 14.1694
A8: 7 | B8: CA-2016-115812 | C8: 42530 | D8: Standard Class | E8: Brosina Hoffman | F8: Los Angeles | G8: California | H8: West | I8: Office Supplies | J8: Art | K8: Newell 322 | L8: 7.28 | M8: 4 | N8: 0 | O8: 1.9656
A9: 8 | B9: CA-2016-115812 | C9: 42530 | D9: Standard Class | E9: Brosina Hoffman | F9: Los Angeles | G9: California | H9: West | I9: Technology | J9: Phones | K9: Mitel 5320 IP Phone VoIP phone | L9: 907.152 | M9: 6 | N9: 0.2 | O9: 90.7152
A10: 9 | B10: CA-2016-115812 | C10: 42530 | D10: Standard Class | E10: Brosina Hoffman | F10: Los Angeles | G10: California | H10: West | I10: Office Supplies | J10: Binders | K10: DXL Angle-View Binders with Locking Rings by Samsill | L10: 18.504 | M10: 3 | N10: 0.2 | O10: 5.7825
A11: 10 | B11: CA-2016-115812 | C11: 42530 | D11: Standard Class | E11: Brosina Hoffman | F11: Los Angeles | G11: California | H11: West | I11: Office Supplies | J11: Appliances | K11: Belkin F5C206VTEL 6 Outlet Surge | L11: 114.9 | M11: 5 | N11: 0 | O11: 34.47
A12: 11 | B12: CA-2016-115812 | C12: 42530 | D12: Standard Class | E12: Brosina Hoffman | F12: Los Angeles | G12: California | H12: West | I12: Furniture | J12: Tables | K12: Chromcraft Rectangular Conference Tables | L12: 1706.184 | M12: 9 | N12: 0.2 | O12: 85.3092
A13: 12 | B13: CA-2016-115812 | C13: 42530 | D13: Standard Class | E13: Brosina Hoffman | F13: Los Angeles | G13: California | H13: West | I13: Technology | J13: Phones | K13: Konftel 250 Conference phone - Charcoal black | L13: 911.424 | M13: 4 | N13: 0.2 | O13: 68.3568
... A1001: 1000 | B1001: CA-2017-162537 | C1001: 43036 | D1001: Standard Class | E1001: Rob Dowd | F1001: Henderson | G1001: Kentucky | H1001: South | I1001: Furniture | J1001: Furnishings | K1001: C-Line Cubicle Keepers Polyproplyene Holder With Velcro Backings | L1001: 33.11 | M1001: 7 | N1001: 0 | O1001: 12.9129

Sheet PT RANGE
G15: Sum of Sales | I15: Region
G16: Years (Order Date) | H16: Quarters (Order Date) | I16: Central | J16: East | K16: South | L16: West
G17: 2016 | H17: Qtr1 | I17: 797.504 | J17: 438.72 | K17: 1732.328 | L17: 587.136
H18: Qtr2 | I18: 5031.882 | J18: 2835.385 | K18: 4109.522 | L18: 5292.354
H19: Qtr3 | I19: 16964.928 | J19: 1420.01 | K19: 949.774 | L19: 7758.264
H20: Qtr4 | I20: 4830.1 | J20: 6331.604 | K20: 969.65 | L20: 8478.108
G21: 2017 | H21: Qtr1 | I21: 768.198 | J21: 1924.678 | K21: 8130.954 | L21: 987.17
H22: Qtr2 | I22: 509.225 | J22: 1133.222 | K22: 1881.604 | L22: 1380.956
H23: Qtr3 | I23: 4408.131 | J23: 4084.53 | K23: 566.894 | L23: 4862.151
H24: Qtr4 | I24: 4442.3572 | J24: 4587.078 | K24: 2962.889 | L24: 3890.092
G25: 2018 | H25: Qtr1 | I25: 258.848 | J25: 1479.46 | K25: 458.746 | L25: 742.851
H26: Qtr2 | I26: 2871.296 | J26: 4307.17 | K26: 4429.862 | L26: 8429.729
H27: Qtr3 | I27: 5227.0476 | J27: 10095.398 | K27: 753.409 | L27: 5544.28
H28: Qtr4 | I28: 7196.61 | J28: 6657.64 | K28: 2414.706 | L28: 4810.156
G29: 2019 | H29: Qtr1 | I29: 4115.4468 | J29: 416.472 | K29: 668.54 | L29: 5123.846
H30: Qtr2 | I30: 1554.337 | J30: 3020.408 | K30: 2848.0265 | L30: 4057.811
H31: Qtr3 | I31: 4700.552 | J31: 2655.166 | K31: 1466.952 | L31: 583.85
H32: Qtr4 | I32: 3333.3858 | J32: 8104.7 | K32: 9220.102 | L32: 8536.566

Sheet table
A1: Row ID | B1: Order ID | C1: Order Date | D1: Ship Mode | E1: Customer Name | F1: City | G1: State | H1: Region | I1: Category | J1: Sub-Category | K1: Product Name | L1: Sales | M1: Quantity | N1: Discount | O1: Profit
A2: 1 | B2: CA-2018-152156 | C2: 43412 | D2: Second Class | E2: Claire Gute | F2: Henderson | G2: Kentucky | H2: South | I2: Furniture | J2: Bookcases | K2: Bush Somerset Collection Bookcase | L2: 261.96 | M2: 2 | N2: 0 | O2: 41.9136
A3: 2 | B3: CA-2018-152156 | C3: 43412 | D3: Second Class | E3: Claire Gute | F3: Henderson | G3: Kentucky | H3: South | I3: Furniture | J3: Chairs | K3: Hon Deluxe Fabric Upholstered Stacking Chairs, Rounded Back | L3: 731.94 | M3: 3 | N3: 0 | O3: 219.582
A4: 3 | B4: CA-2018-138688 | C4: 43263 | D4: Second Class | E4: Darrin Van Huff | F4: Los Angeles | G4: California | H4: West | I4: Office Supplies | J4: Labels | K4: Self-Adhesive Address Labels for Typewriters by Universal | L4: 14.62 | M4: 2 | N4: 0 | O4: 6.8714
A5: 4 | B5: US-2017-108966 | C5: 43019 | D5: Standard Class | E5: Sean O'Donnell | F5: Fort Lauderdale | G5: Florida | H5: South | I5: Furniture | J5: Tables | K5: Bretford CR4500 Series Slim Rectangular Table | L5: 957.5775 | M5: 5 | N5: 0.45 | O5: -383.031
A6: 5 | B6: US-2017-108966 | C6: 43019 | D6: Standard Class | E6: Sean O'Donnell | F6: Fort Lauderdale | G6: Florida | H6: South | I6: Office Supplies | J6: Storage | K6: Eldon Fold 'N Roll Cart System | L6: 22.368 | M6: 2 | N6: 0.2 | O6: 2.5164
A7: 6 | B7: CA-2016-115812 | C7: 42530 | D7: Standard Class | E7: Brosina Hoffman | F7: Los Angeles | G7: California | H7: West | I7: Furniture | J7: Furnishings | K7: Eldon Expressions Wood and Plastic Desk Accessories, Cherry Wood | L7: 48.86 | M7: 7 | N7: 0 | O7: 14.1694
A8: 7 | B8: CA-2016-115812 | C8: 42530 | D8: Standard Class | E8: Brosina Hoffman | F8: Los Angeles | G8: California | H8: West | I8: Office Supplies | J8: Art | K8: Newell 322 | L8: 7.28 | M8: 4 | N8: 0 | O8: 1.9656
A9: 8 | B9: CA-2016-115812 | C9: 42530 | D9: Standard Class | E9: Brosina Hoffman | F9: Los Angeles | G9: California | H9: West | I9: Technology | J9: Phones | K9: Mitel 5320 IP Phone VoIP phone | L9: 907.152 | M9: 6 | N9: 0.2 | O9: 90.7152
A10: 9 | B10: CA-2016-115812 | C10: 42530 | D10: Standard Class | E10: Brosina Hoffman | F10: Los Angeles | G10: California | H10: West | I10: Office Supplies | J10: Binders | K10: DXL Angle-View Binders with Locking Rings by Samsill | L10: 18.504 | M10: 3 | N10: 0.2 | O10: 5.7825
A11: 10 | B11: CA-2016-115812 | C11: 42530 | D11: Standard Class | E11: Brosina Hoffman | F11: Los Angeles | G11: California | H11: West | I11: Office Supplies | J11: Appliances | K11: Belkin F5C206VTEL 6 Outlet Surge | L11: 114.9 | M11: 5 | N11: 0 | O11: 34.47
A12: 11 | B12: CA-2016-115812 | C12: 42530 | D12: Standard Class | E12: Brosina Hoffman | F12: Los Angeles | G12: California | H12: West | I12: Furniture | J12: Tables | K12: Chromcraft Rectangular Conference Tables | L12: 1706.184 | M12: 9 | N12: 0.2 | O12: 85.3092
A13: 12 | B13: CA-2016-115812 | C13: 42530 | D13: Standard Class | E13: Brosina Hoffman | F13: Los Angeles | G13: California | H13: West | I13: Technology | J13: Phones | K13: Konftel 250 Conference phone - Charcoal black | L13: 911.424 | M13: 4 | N13: 0.2 | O13: 68.3568
... A1001: 1000 | B1001: CA-2017-162537 | C1001: 43036 | D1001: Standard Class | E1001: Rob Dowd | F1001: Henderson | G1001: Kentucky | H1001: South | I1001: Furniture | J1001: Furnishings | K1001: C-Line Cubicle Keepers Polyproplyene Holder With Velcro Backings | L1001: 33.11 | M1001: 7 | N1001: 0 | O1001: 12.9129

Sheet PT TABLE
AJ3: =T4 -> State | AK3: =U4 -> Count of Order ID
A4: Count of Order ID | B4: Region | J4: Sub-Category | K4: Sum of Sales | L4: Count of Order ID | P4: Ship Mode | Q4: Sum of Profit | T4: State | U4: Count of Order ID | Y4: Sum of Sales | AA4: Region | AG4: Region | AH4: Sum of Sales | AJ4: =T5 -> Alabama | AK4: =U5 -> 4
A5: Category | B5: Central | C5: East | D5: South | E5: West | J5: Accessories | K5: 20481.394 | L5: 83 | P5: First Class | Q5: 4804.9781 | T5: Alabama | U5: 4 | Y5: Years (Order Date) | Z5: Quarters (Order Date) | AA5: Central | AB5: East | AC5: South | AD5: West | AG5: Central | AH5: 67009.848 | AJ5: =T6 -> Arizona | AK5: =U6 -> 23
A6: Furniture | B6: 49 | C6: 60 | D6: 35 | E6: 63 | J6: Appliances | K6: 8369.878 | L6: 43 | P6: Same Day | Q6: -2832.7894 | T6: Arizona | U6: 23 | Y6: 2016 | Z6: Qtr1 | AA6: 797.504 | AB6: 438.72 | AC6: 1732.328 | AD6: 587.136 | AG6: East | AH6: 59491.641 | AJ6: =T7 -> Arkansas | AK6: =U7 -> 2
A7: Office Supplies | B7: 144 | C7: 201 | D7: 80 | E7: 178 | J7: Art | K7: 3858.084 | L7: 81 | P7: Second Class | Q7: 4278.3373 | T7: Arkansas | U7: 2 | Z7: Qtr2 | AA7: 5031.882 | AB7: 2835.385 | AC7: 4109.522 | AD7: 5292.354 | AG7: South | AH7: 43563.958 | AJ7: =T8 -> California | AK7: =U8 -> 183 | AO7: Sum of Profit | AR7: Sum of Margin
A8: Technology | B8: 52 | C8: 52 | D8: 26 | E8: 60 | J8: Binders | K8: 21412.529 | L8: 145 | P8: Standard Class | Q8: 12495.653 | T8: California | U8: 183 | Z8: Qtr3 | AA8: 16964.928 | AB8: 1420.01 | AC8: 949.774 | AD8: 7758.264 | AG8: West | AH8: 71065.32 | AJ8: =T9 -> Colorado | AK8: =U9 -> 35 | AM8: Sum of Sales | AO8: 18746.179 | AR8: 0.077742792
J9: Bookcases | K9: 13834.99 | L9: 21 | T9: Colorado | U9: 35 | Z9: Qtr4 | AA9: 4830.1 | AB9: 6331.604 | AC9: 969.65 | AD9: 8478.108 | AJ9: =T10 -> Connecticut | AK9: =U10 -> 6 | AM9: 241130.77
J10: Chairs | K10: 30809.088 | L10: 58 | T10: Connecticut | U10: 6 | Y10: 2017 | Z10: Qtr1 | AA10: 768.198 | AB10: 1924.678 | AC10: 8130.954 | AD10: 987.17 | AJ10: =T11 -> Delaware | AK10: =U11 -> 8
J11: Copiers | K11: 9359.832 | L11: 6 | T11: Delaware | U11: 8 | Z11: Qtr2 | AA11: 509.225 | AB11: 1133.222 | AC11: 1881.604 | AD11: 1380.956 | AJ11: =T12 -> Florida | AK11: =U12 -> 42
J12: Envelopes | K12: 2109.332 | L12: 30 | T12: Florida | U12: 42 | Z12: Qtr3 | AA12: 4408.131 | AB12: 4084.53 | AC12: 566.894 | AD12: 4862.151 | AJ12: =T13 -> Georgia | AK12: =U13 -> 8 | BB12: Customer Name | BC12: Sum of Sales
J13: Fasteners | K13: 381.66 | L13: 21 | T13: Georgia | U13: 8 | Z13: Qtr4 | AA13: 4442.3572 | AB13: 4587.078 | AC13: 2962.889 | AD13: 3890.092 | AJ13: =T14 -> Illinois | AK13: =U14 -> 52 | BB13: Becky Martin | BC13: 10539.896
J14: Furnishings | K14: 10256.894 | L14: 95 | T14: Illinois | U14: 52 | Y14: 2018 | Z14: Qtr1 | AA14: 258.848 | AB14: 1479.46 | AC14: 458.746 | AD14: 742.851 | AJ14: =T15 -> Indiana | AK14: =U15 -> 10 | BB14: Grant Thornton | BC14: 8167.42
J15: Labels | K15: 1534.34 | L15: 41 | T15: Indiana | U15: 10 | Z15: Qtr2 | AA15: 2871.296 | AB15: 4307.17 | AC15: 4429.862 | AD15: 8429.729 | AJ15: =T16 -> Iowa | AK15: =U16 -> 8 | BB15: Christopher Martinez | BC15: 6412.77
J16: Machines | K16: 32622.116 | L16: 13 | T16: Iowa | U16: 8 | Z16: Qtr3 | AA16: 5227.0476 | AB16: 10095.398 | AC16: 753.409 | AD16: 5544.28 | AJ16: =T17 -> Kentucky | AK16: =U17 -> 18 | BB16: Sean Braxton | BC16: 5579.94
J17: Paper | K17: 6386.24 | L17: 127 | T17: Kentucky | U17: 18 | Z17: Qtr4 | AA17: 7196.61 | AB17: 6657.64 | AC17: 2414.706 | AD17: 4810.156 | AJ17: =T18 -> Louisiana | AK17: =U18 -> 9 | BB17: Nathan Mautz | BC17: 4807.372
J18: Phones | K18: 31036.5 | L18: 88 | T18: Louisiana | U18: 9 | Y18: 2019 | Z18: Qtr1 | AA18: 4115.4468 | AB18: 416.472 | AC18: 668.54 | AD18: 5123.846 | AJ18: =T19 -> Maryland | AK18: =U19 -> 1
J19: Storage | K19: 21809.636 | L19: 95 | T19: Maryland | U19: 1 | Z19: Qtr2 | AA19: 1554.337 | AB19: 3020.408 | AC19: 2848.0265 | AD19: 4057.811 | AJ19: =T20 -> Massachusetts | AK19: =U20 -> 8
J20: Supplies | K20: 2391.648 | L20: 20 | T20: Massachusetts | U20: 8 | Z20: Qtr3 | AA20: 4700.552 | AB20: 2655.166 | AC20: 1466.952 | AD20: 583.85 | AJ20: =T21 -> Michigan | AK20: =U21 -> 42
J21: Tables | K21: 24476.606 | L21: 33 | T21: Michigan | U21: 42 | Z21: Qtr4 | AA21: 3333.3858 | AB21: 8104.7 | AC21: 9220.102 | AD21: 8536.566 | AJ21: =T22 -> Minnesota | AK21: =U22 -> 21
T22: Minnesota | U22: 21 | AJ22: =T23 -> Mississippi | AK22: =U23 -> 6
T23: Mississippi | U23: 6 | AJ23: =T24 -> Missouri | AK23: =U24 -> 3
T24: Missouri | U24: 3 | AJ24: =T25 -> Montana | AK24: =U25 -> 4
T25: Montana | U25: 4 | AJ25: =T26 -> Nebraska | AK25: =U26 -> 4
T26: Nebraska | U26: 4 | AJ26: =T27 -> Nevada | AK26: =U27 -> 1
T27: Nevada | U27: 1 | AJ27: =T28 -> New Hampshire | AK27: =U28 -> 4
T28: New Hampshire | U28: 4 | AJ28: =T29 -> New Jersey | AK28: =U29 -> 16
T29: New Jersey | U29: 16 | AJ29: =T30 -> New Mexico | AK29: =U30 -> 2
T30: New Mexico | U30: 2 | AJ30: =T31 -> New York | AK30: =U31 -> 135 | AU30: Count of Order ID
T31: New York | U31: 135 | AJ31: =T32 -> North Carolina | AK31: =U32 -> 22 | AU31: 1000
T32: North Carolina | U32: 22 | AJ32: =T33 -> Ohio | AK32: =U33 -> 54
T33: Ohio | U33: 54 | AJ33: =T34 -> Oklahoma | AK33: =U34 -> 3
T34: Oklahoma | U34: 3 | AJ34: =T35 -> Oregon | AK34: =U35 -> 9
T35: Oregon | U35: 9 | AJ35: =T36 -> Pennsylvania | AK35: =U36 -> 79
T36: Pennsylvania | U36: 79 | AJ36: =T37 -> Rhode Island | AK36: =U37 -> 2
T37: Rhode Island | U37: 2 | AJ37: =T38 -> South Carolina | AK37: =U38 -> 2
T38: South Carolina | U38: 2 | AJ38: =T39 -> Tennessee | AK38: =U39 -> 10
T39: Tennessee | U39: 10 | AJ39: =T40 -> Texas | AK39: =U40 -> 92
T40: Texas | U40: 92 | AJ40: =T41 -> Utah | AK40: =U41 -> 5
T41: Utah | U41: 5 | AJ41: =T42 -> Virginia | AK41: =U42 -> 18
T42: Virginia | U42: 18 | AJ42: =T43 -> Washington | AK42: =U43 -> 39
...

Sheet dashbord home
J2: =GETPIVOTDATA("Sales",'PT TABLE'!$AM$8) -> 241130.77 | P2: =GETPIVOTDATA("Profit",'PT TABLE'!$AO$7) -> 18746.179 | V2: =GETPIVOTDATA("Order ID",'PT TABLE'!$AU$30) -> 1000 | AB2: =GETPIVOTDATA("Margin",'PT TABLE'!$AR$7) -> 0.077742792

Sheet dashbord details
J2: =GETPIVOTDATA("Sales",'PT TABLE'!$AM$8) -> 241130.77 | P2: =GETPIVOTDATA("Profit",'PT TABLE'!$AO$7) -> 18746.179 | V2: =GETPIVOTDATA("Order ID",'PT TABLE'!$AU$30) -> 1000 | AB2: =GETPIVOTDATA("Margin",'PT TABLE'!$AR$7) -> 0.077742792

Sheet  dashbord map
J2: =GETPIVOTDATA("Sales",'PT TABLE'!$AM$8) -> 241130.77 | P2: =GETPIVOTDATA("Profit",'PT TABLE'!$AO$7) -> 18746.179 | V2: =GETPIVOTDATA("Order ID",'PT TABLE'!$AU$30) -> 1000 | AB2: =GETPIVOTDATA("Margin",'PT TABLE'!$AR$7) -> 0.077742792
